Workbook
Name Slicer_Class: #N/A
Name Slicer_Term: #N/A

Sheet Results
A1: Student ID | B1: Student Name | C1: Gender | D1: Class | E1: Term | F1: Maths | G1: English | H1: Basic Science | I1: Social Studies | J1: Computer Studies | K1: Civic Education
A2: STU001 | B2: John Danjuma | C2: MALE | D2: JSS1A | E2: First Term | F2: 74 | G2: 69 | H2: 69 | I2: 84 | J2: 91 | K2: 87
A3: STU001 | B3: John Danjuma | C3: male | D3: JSS1A | E3: Second Term | F3: 79 | G3: 88 | H3: 82 | I3: 73 | J3: 80 | K3: 87
A4: STU001 | B4: John Danjuma | C4: Male | D4: JSS1 A | E4: Third Term | F4: 67 | G4: 79 | H4: 63 | I4: 73 | J4: 84 | K4: 67
A5: STU002 | B5: Damilola Danjuma | C5: Female | D5: JSS1A | E5: First Term | F5: 37 | G5: 51 | H5: 37 | I5: 54 | J5: 49 | K5: 55
A6: STU002 | B6: damilola danjuma | C6: FEMALE | D6: JSS1A | E6: Second Term | F6: 41 | G6: 50 | H6: 43 | I6: 53 | J6: 49 | K6: 59
A7: STU002 | B7: Damilola Danjuma | C7: Female | D7: JSS1A | E7: Third Term | F7: 53 | G7: 49 | H7: 46 | I7: 42 | J7: 56 | K7: 48
A8: STU003 | B8: Khadija Johnson | C8: Female | D8: JSS1A | E8: First Term | F8: 56 | G8: 71 | H8: 67 | I8: 78 | J8: 81 | K8: 70
A9: STU003 | B9: Khadija Johnson | C9: female | D9: JSS1A | E9: Second Term | F9: 56 | G9: 74 | H9: 66 | I9: 69 | J9: 74 | K9: 63
A10: STU003 | B10: Khadija Johnson | C10: Female | D10: JSS1A | E10: Third Term | F10: 54 | G10: 65 | H10: 65 | I10: 53 | J10: 58 | K10: 64
A11: STU004 | B11: Favour Yakubu | C11: Female | D11: JSS1A | E11: First Term | F11: 70 | G11: 75 | H11: 81 | I11: 78 | J11: 69 | K11: 86
A12: STU004 | B12: Favour Yakubu | C12: Female | D12: JSS1A | E12: Second Term | F12: 68 | G12: 72 | H12: 64 | I12: 87 | J12: 66 | K12: 71
A13: STU004 | B13: Favour Yakubu | C13: F | D13: jss1a | E13: Third Term | F13: 69 | G13: 85 | H13: 84 | I13: 72 | J13: 79 | K13: 72
A14: STU005 | B14: Emeka Olawale | C14: Male | D14: JSS1A | E14: First Term | F14: 62 | G14: 50 | H14: 58 | I14: 71 | J14: 63 | K14: 77
A15: STU005 | B15: Emeka Olawale | C15: M | D15: JSS1A | E15: Second Term | F15: 50 | G15: 65 | H15: 66 | I15: 64 | J15: 76 | K15: 72
A16: STU005 | B16: Emeka Olawale | C16: male | D16: Jss1A | E16: Third Term | F16: 46 | G16: 91 | H16: 66 | I16: 67 | J16: 57 | K16: 70
A17: STU006 | B17: John Anyanwu | C17: Male | D17: JSS1A | E17: First Term | F17: 65 | G17: 79 | H17: 75 | I17: 91 | J17: 80 | K17: 84
A18: STU006 | B18: John Anyanwu | C18: Male | D18: JSS1A | E18: Second Term | F18: 66 | G18: 68 | H18: 66 | I18: 80 | J18: 79 | K18: 71
A19: STU006 | B19: John Anyanwu | C19: male | D19: JSS1A | E19: Third Term | F19: 50 | H19: 70 | I19: 67 | J19: 80 | K19: 65
A20: STU007 | B20: Zainab Ogunleye | C20: Female | D20: JSS1 A | E20: First Term | F20: 48 | G20: 36 | H20: 47 | I20: 54 | J20: 61 | K20: 71
A21: STU007 | B21: Zainab Ogunleye | C21: F | D21: JSS1A | E21: Second Term | F21: 48 | G21: 64 | H21: 56 | I21: 64 | J21: 55 | K21: 69
A22: STU007 | B22: Zainab Ogunleye | C22: Female | D22: JSS1 A | E22: Third Term | F22: 41 | G22: 58 | H22: 46 | I22: 54 | J22: 48 | K22: 57
A23: STU008 | B23: Obiageli Umar | C23: Female | D23: JSS1A | E23: First Term | F23: 67 | G23: 70 | H23: 59 | I23: 84 | J23: 77 | K23: 84
A24: STU008 | B24: Obiageli Umar | C24: female | D24: JSS1A | E24: Second Term | F24: 68 | G24: 64 | H24: 53 | I24: 65 | J24: 81 | K24: 67
A25: STU008 | B25: Obiageli Umar | C25: Female | D25: JSS1A | E25: Third Term | F25: 67 | G25: 63 | H25: 68 | I25: 57 | J25: 79 | K25: 73
A26: STU009 | B26: Nkechi Adebayo | C26: Female | D26: JSS1A | E26: First Term | F26: 55 | G26: 56 | H26: 59 | I26: 57 | J26: 64 | K26: 50
A27: STU009 | B27: Nkechi Adebayo | C27: Female | D27: JSS1A | E27: Second Term | F27: 40 | G27: 59 | H27: 52 | I27: 55 | J27: 57 | K27: 63
A28: STU009 | B28: Nkechi Adebayo | C28: Female | D28: JSS1A | E28: Third Term | F28: 43 | G28: 56 | H28: 44 | I28: 53 | J28: 64 | K28: 66
A29: STU010 | B29: Olumide Umar | C29: Male | D29: JSS1A | E29: First Term | F29: 44 | G29: 63 | H29: 48 | I29: 66 | J29: 48 | K29: 56
A30: STU010 | B30: Olumide Umar | C30: Male | D30: JSS1A | E30: Second Term | F30: 52 | G30: 60 | H30: 70 | I30: 71 | J30: 77 | K30: 76
A31: STU010 | B31: Olumide Umar | C31: Male | D31: JSS1A | E31: Third Term | F31: 58 | G31: 64 | H31: 71 | I31: 69 | J31: 68 | K31: 62
A32: STU011 | B32: Daniel Onyeka | C32: Male | D32: Jss1A | E32: First Term | F32: 37 | G32: 24 | H32: 39 | I32: 40 | J32: 53 | K32: 46
A33: STU011 | B33: Daniel Onyeka | C33: Male | D33: jss1a | E33: Second Term | F33: 41 | G33: 59 | H33: 40 | I33: 55 | J33: 41 | K33: 56
A34: STU011 | B34: Daniel Onyeka | C34: Male | D34: JSS1A | E34: Third Term | F34: 53 | G34: 62 | I34: 61 | J34: 62 | K34: 62
A35: STU012 | B35: Daniel Kalu | C35: Male | D35: JSS1A | E35: First Term | F35: 63 | G35: 71 | H35: 69 | I35: 64 | J35: 63 | K35: 91
A36: STU012 | B36: Daniel Kalu | C36: Male | D36: JSS1A | E36: Second Term | F36: 79 | G36: 62 | H36: 73 | I36: 79 | J36: 81 | K36: 79
A37: STU012 | B37: Daniel Kalu | C37: Male | D37: JSS1A | E37: Third Term | F37: 63 | G37: 74 | H37: 70 | I37: 79 | J37: 77 | K37: 80
A38: STU013 | B38: Sani Adewale | C38: Male | D38: JSS1A | E38: First Term | F38: 69 | G38: 76 | H38: 58 | I38: 68 | J38: 66 | K38: 82
A39: STU013 | B39: Sani Adewale | C39: Male | D39: JSS1A | E39: Second Term | F39: 61 | G39: 78 | H39: 62 | I39: 71 | J39: 62 | K39: 83
A40: STU013 | B40: sani adewale | C40: M | D40: jss1a | E40: Third Term | F40: 58 | G40: 57 | H40: 61 | I40: 54 | J40: 71 | K40: 74
...

Sheet Cleaned Data
A1: Student ID | B1: Student Name | C1: Gender | D1: Class | E1: Term | F1: Maths | G1: English | H1: Basic Science | I1: Social Studies | J1: Computer Studies | K1: Civic Education | L1: Total | M1: Average | N1: Grade | O1: Class Rank
A2: STU001 | B2: John Danjuma | C2: Male | D2: JSS1A | E2: First Term | F2: 74 | G2: 69 | H2: 69 | I2: 84 | J2: 91 | K2: 87 | L2: =SUM(F2:K2) -> 474 | M2: =AVERAGE(F2:K2) -> 79 | N2: {=_xlfn.IFS(M2>=70,"A",M2>=60,"B",M2>=50,"C",M2>=45,"D",M2>=40,"E",TRUE,"F")} -> A | O2: =COUNTIFS($D$2:$D$721,D2,$E$2:$E$721,E2,$M$2:$M$721,">"&M2)+1 -> 2
A3: STU001 | B3: John Danjuma | C3: Male | D3: JSS1A | E3: Second Term | F3: 79 | G3: 88 | H3: 82 | I3: 73 | J3: 80 | K3: 87 | L3: =SUM(F3:K3) -> 489 | M3: =AVERAGE(F3:K3) -> 81.5 | N3: {=_xlfn.IFS(M3>=70,"A",M3>=60,"B",M3>=50,"C",M3>=45,"D",M3>=40,"E",TRUE,"F")} -> A | O3: =COUNTIFS($D$2:$D$721,D3,$E$2:$E$721,E3,$M$2:$M$721,">"&M3)+1 -> 3 | Q3: STUDENT NAME | R3: CLASS | S3: AVERAGE | U3: STUDENT NAME | V3: CLASS | W3: AVERAGE
A4: STU001 | B4: John Danjuma | C4: Male | D4: JSS1A | E4: Third Term | F4: 67 | G4: 79 | H4: 63 | I4: 73 | J4: 84 | K4: 67 | L4: =SUM(F4:K4) -> 433 | M4: =AVERAGE(F4:K4) -> 72.166667 | N4: {=_xlfn.IFS(M4>=70,"A",M4>=60,"B",M4>=50,"C",M4>=45,"D",M4>=40,"E",TRUE,"F")} -> A | O4: =COUNTIFS($D$2:$D$721,D4,$E$2:$E$721,E4,$M$2:$M$721,">"&M4)+1 -> 8 | Q4: {=INDEX($B$2:$B$721,MATCH(1,($E$2:$E$721="Third Term")*($M$2:$M$721=S4)*(COUNTIF($Q$3:Q3,$B$2:$B$721)=0),0))} -> Sade Umar | R4: {=INDEX($D$2:$D$721,MATCH(1,($B$2:$B$721=Q4)*($M$2:$M$721=S4)*($E$2:$E$721="Third Term"),0))} -> JSS2B | S4: {=LARGE(_xlfn._xlws.FILTER($M$2:$M$721,$E$2:$E$721="Third Term"), ROWS($S$4:S4))} -> 96.666667 | U4: Abdullah Akinola | V4: Third Term | W4: 88.8
A5: STU002 | B5: Damilola Danjuma | C5: Female | D5: JSS1A | E5: First Term | F5: 37 | G5: 51 | H5: 37 | I5: 54 | J5: 49 | K5: 55 | L5: =SUM(F5:K5) -> 283 | M5: =AVERAGE(F5:K5) -> 47.166667 | N5: {=_xlfn.IFS(M5>=70,"A",M5>=60,"B",M5>=50,"C",M5>=45,"D",M5>=40,"E",TRUE,"F")} -> D | O5: =COUNTIFS($D$2:$D$721,D5,$E$2:$E$721,E5,$M$2:$M$721,">"&M5)+1 -> 35 | Q5: {=INDEX($B$2:$B$721,MATCH(1,($E$2:$E$721="Third Term")*($M$2:$M$721=S5)*(COUNTIF($Q$3:Q4,$B$2:$B$721)=0),0))} -> Dare Musa | R5: {=INDEX($D$2:$D$721,MATCH(1,($B$2:$B$721=Q5)*($M$2:$M$721=S5)*($E$2:$E$721="Third Term"),0))} -> JSS2B | S5: {=LARGE(_xlfn._xlws.FILTER($M$2:$M$721,$E$2:$E$721="Third Term"), ROWS($S$4:S5))} -> 93.5 | U5: Segun Adeyemi | V5: Third Term | W5: 85.833333
A6: STU002 | B6: Damilola Danjuma | C6: Female | D6: JSS1A | E6: Second Term | F6: 41 | G6: 50 | H6: 43 | I6: 53 | J6: 49 | K6: 59 | L6: =SUM(F6:K6) -> 295 | M6: =AVERAGE(F6:K6) -> 49.166667 | N6: {=_xlfn.IFS(M6>=70,"A",M6>=60,"B",M6>=50,"C",M6>=45,"D",M6>=40,"E",TRUE,"F")} -> D | O6: =COUNTIFS($D$2:$D$721,D6,$E$2:$E$721,E6,$M$2:$M$721,">"&M6)+1 -> 34 | Q6: {=INDEX($B$2:$B$721,MATCH(1,($E$2:$E$721="Third Term")*($M$2:$M$721=S6)*(COUNTIF($Q$3:Q5,$B$2:$B$721)=0),0))} -> Nnamdi Ibrahim | R6: {=INDEX($D$2:$D$721,MATCH(1,($B$2:$B$721=Q6)*($M$2:$M$721=S6)*($E$2:$E$721="Third Term"),0))} -> JSS1B | S6: {=LARGE(_xlfn._xlws.FILTER($M$2:$M$721,$E$2:$E$721="Third Term"), ROWS($S$4:S6))} -> 91.5 | U6: Comfort Okonkwo | V6: Third Term | W6: 84.5
A7: STU002 | B7: Damilola Danjuma | C7: Female | D7: JSS1A | E7: Third Term | F7: 53 | G7: 49 | H7: 46 | I7: 42 | J7: 56 | K7: 48 | L7: =SUM(F7:K7) -> 294 | M7: =AVERAGE(F7:K7) -> 49 | N7: {=_xlfn.IFS(M7>=70,"A",M7>=60,"B",M7>=50,"C",M7>=45,"D",M7>=40,"E",TRUE,"F")} -> D | O7: =COUNTIFS($D$2:$D$721,D7,$E$2:$E$721,E7,$M$2:$M$721,">"&M7)+1 -> 37 | Q7: {=INDEX($B$2:$B$721,MATCH(1,($E$2:$E$721="Third Term")*($M$2:$M$721=S7)*(COUNTIF($Q$3:Q6,$B$2:$B$721)=0),0))} -> Yetunde Adebayo | R7: {=INDEX($D$2:$D$721,MATCH(1,($B$2:$B$721=Q7)*($M$2:$M$721=S7)*($E$2:$E$721="Third Term"),0))} -> JSS2A | S7: {=LARGE(_xlfn._xlws.FILTER($M$2:$M$721,$E$2:$E$721="Third Term"), ROWS($S$4:S7))} -> 91
A8: STU003 | B8: Khadija Johnson | C8: Female | D8: JSS1A | E8: First Term | F8: 56 | G8: 71 | H8: 67 | I8: 78 | J8: 81 | K8: 70 | L8: =SUM(F8:K8) -> 423 | M8: =AVERAGE(F8:K8) -> 70.5 | N8: {=_xlfn.IFS(M8>=70,"A",M8>=60,"B",M8>=50,"C",M8>=45,"D",M8>=40,"E",TRUE,"F")} -> A | O8: =COUNTIFS($D$2:$D$721,D8,$E$2:$E$721,E8,$M$2:$M$721,">"&M8)+1 -> 8 | Q8: {=INDEX($B$2:$B$721,MATCH(1,($E$2:$E$721="Third Term")*($M$2:$M$721=S8)*(COUNTIF($Q$3:Q7,$B$2:$B$721)=0),0))} -> Michael Amadi | R8: {=INDEX($D$2:$D$721,MATCH(1,($B$2:$B$721=Q8)*($M$2:$M$721=S8)*($E$2:$E$721="Third Term"),0))} -> JSS2A | S8: {=LARGE(_xlfn._xlws.FILTER($M$2:$M$721,$E$2:$E$721="Third Term"), ROWS($S$4:S8))} -> 90.333333
A9: STU003 | B9: Khadija Johnson | C9: Female | D9: JSS1A | E9: Second Term | F9: 56 | G9: 74 | H9: 66 | I9: 69 | J9: 74 | K9: 63 | L9: =SUM(F9:K9) -> 402 | M9: =AVERAGE(F9:K9) -> 67 | N9: {=_xlfn.IFS(M9>=70,"A",M9>=60,"B",M9>=50,"C",M9>=45,"D",M9>=40,"E",TRUE,"F")} -> B | O9: =COUNTIFS($D$2:$D$721,D9,$E$2:$E$721,E9,$M$2:$M$721,">"&M9)+1 -> 13 | Q9: {=INDEX($B$2:$B$721,MATCH(1,($E$2:$E$721="Third Term")*($M$2:$M$721=S9)*(COUNTIF($Q$3:Q8,$B$2:$B$721)=0),0))} -> Tolu Williams | R9: {=INDEX($D$2:$D$721,MATCH(1,($B$2:$B$721=Q9)*($M$2:$M$721=S9)*($E$2:$E$721="Third Term"),0))} -> JSS3B | S9: {=LARGE(_xlfn._xlws.FILTER($M$2:$M$721,$E$2:$E$721="Third Term"), ROWS($S$4:S9))} -> 89.5
A10: STU003 | B10: Khadija Johnson | C10: Female | D10: JSS1A | E10: Third Term | F10: 54 | G10: 65 | H10: 65 | I10: 53 | J10: 58 | K10: 64 | L10: =SUM(F10:K10) -> 359 | M10: =AVERAGE(F10:K10) -> 59.833333 | N10: {=_xlfn.IFS(M10>=70,"A",M10>=60,"B",M10>=50,"C",M10>=45,"D",M10>=40,"E",TRUE,"F")} -> C | O10: =COUNTIFS($D$2:$D$721,D10,$E$2:$E$721,E10,$M$2:$M$721,">"&M10)+1 -> 26 | Q10: {=INDEX($B$2:$B$721,MATCH(1,($E$2:$E$721="Third Term")*($M$2:$M$721=S10)*(COUNTIF($Q$3:Q9,$B$2:$B$721)=0),0))} -> Daniel Oyewole | R10: {=INDEX($D$2:$D$721,MATCH(1,($B$2:$B$721=Q10)*($M$2:$M$721=S10)*($E$2:$E$721="Third Term"),0))} -> JSS3B | S10: {=LARGE(_xlfn._xlws.FILTER($M$2:$M$721,$E$2:$E$721="Third Term"), ROWS($S$4:S10))} -> 89.333333
A11: STU004 | B11: Favour Yakubu | C11: Female | D11: JSS1A | E11: First Term | F11: 70 | G11: 75 | H11: 81 | I11: 78 | J11: 69 | K11: 86 | L11: =SUM(F11:K11) -> 459 | M11: =AVERAGE(F11:K11) -> 76.5 | N11: {=_xlfn.IFS(M11>=70,"A",M11>=60,"B",M11>=50,"C",M11>=45,"D",M11>=40,"E",TRUE,"F")} -> A | O11: =COUNTIFS($D$2:$D$721,D11,$E$2:$E$721,E11,$M$2:$M$721,">"&M11)+1 -> 4 | Q11: {=INDEX($B$2:$B$721,MATCH(1,($E$2:$E$721="Third Term")*($M$2:$M$721=S11)*(COUNTIF($Q$3:Q10,$B$2:$B$721)=0),0))} -> Abdullah Akinola | R11: {=INDEX($D$2:$D$721,MATCH(1,($B$2:$B$721=Q11)*($M$2:$M$721=S11)*($E$2:$E$721="Third Term"),0))} -> JSS1A | S11: {=LARGE(_xlfn._xlws.FILTER($M$2:$M$721,$E$2:$E$721="Third Term"), ROWS($S$4:S11))} -> 88.833333 | U11: STUDENT NAME | V11: CLASS | W11: AVERAGE
A12: STU004 | B12: Favour Yakubu | C12: Female | D12: JSS1A | E12: Second Term | F12: 68 | G12: 72 | H12: 64 | I12: 87 | J12: 66 | K12: 71 | L12: =SUM(F12:K12) -> 428 | M12: =AVERAGE(F12:K12) -> 71.333333 | N12: {=_xlfn.IFS(M12>=70,"A",M12>=60,"B",M12>=50,"C",M12>=45,"D",M12>=40,"E",TRUE,"F")} -> A | O12: =COUNTIFS($D$2:$D$721,D12,$E$2:$E$721,E12,$M$2:$M$721,">"&M12)+1 -> 8 | Q12: {=INDEX($B$2:$B$721,MATCH(1,($E$2:$E$721="Third Term")*($M$2:$M$721=S12)*(COUNTIF($Q$3:Q11,$B$2:$B$721)=0),0))} -> Peter Nwankwo | R12: {=INDEX($D$2:$D$721,MATCH(1,($B$2:$B$721=Q12)*($M$2:$M$721=S12)*($E$2:$E$721="Third Term"),0))} -> JSS2A | S12: {=LARGE(_xlfn._xlws.FILTER($M$2:$M$721,$E$2:$E$721="Third Term"), ROWS($S$4:S12))} -> 88.666667 | U12: Nmamdi Ibrahim | V12: Third Term | W12: 91.5
A13: STU004 | B13: Favour Yakubu | C13: Female | D13: JSS1A | E13: Third Term | F13: 69 | G13: 85 | H13: 84 | I13: 72 | J13: 79 | K13: 72 | L13: =SUM(F13:K13) -> 461 | M13: =AVERAGE(F13:K13) -> 76.833333 | N13: {=_xlfn.IFS(M13>=70,"A",M13>=60,"B",M13>=50,"C",M13>=45,"D",M13>=40,"E",TRUE,"F")} -> A | O13: =COUNTIFS($D$2:$D$721,D13,$E$2:$E$721,E13,$M$2:$M$721,">"&M13)+1 -> 4 | Q13: {=INDEX($B$2:$B$721,MATCH(1,($E$2:$E$721="Third Term")*($M$2:$M$721=S13)*(COUNTIF($Q$3:Q12,$B$2:$B$721)=0),0))} -> Ifeoma Lawal | R13: {=INDEX($D$2:$D$721,MATCH(1,($B$2:$B$721=Q13)*($M$2:$M$721=S13)*($E$2:$E$721="Third Term"),0))} -> JSS3A | S13: {=LARGE(_xlfn._xlws.FILTER($M$2:$M$721,$E$2:$E$721="Third Term"), ROWS($S$4:S13))} -> 88.666667 | U13: Emeka Mohammed | V13: Third Term | W13: 84.2
A14: STU005 | B14: Emeka Olawale | C14: Male | D14: JSS1A | E14: First Term | F14: 62 | G14: 50 | H14: 58 | I14: 71 | J14: 63 | K14: 77 | L14: =SUM(F14:K14) -> 381 | M14: =AVERAGE(F14:K14) -> 63.5 | N14: {=_xlfn.IFS(M14>=70,"A",M14>=60,"B",M14>=50,"C",M14>=45,"D",M14>=40,"E",TRUE,"F")} -> B | O14: =COUNTIFS($D$2:$D$721,D14,$E$2:$E$721,E14,$M$2:$M$721,">"&M14)+1 -> 13 | U14: Adaeze Bakare | V14: Third Term | W14: 82.5
A15: STU005 | B15: Emeka Olawale | C15: Male | D15: JSS1A | E15: Second Term | F15: 50 | G15: 65 | H15: 66 | I15: 64 | J15: 76 | K15: 72 | L15: =SUM(F15:K15) -> 393 | M15: =AVERAGE(F15:K15) -> 65.5 | N15: {=_xlfn.IFS(M15>=70,"A",M15>=60,"B",M15>=50,"C",M15>=45,"D",M15>=40,"E",TRUE,"F")} -> B | O15: =COUNTIFS($D$2:$D$721,D15,$E$2:$E$721,E15,$M$2:$M$721,">"&M15)+1 -> 17
A16: STU005 | B16: Emeka Olawale | C16: Male | D16: JSS1A | E16: Third Term | F16: 46 | G16: 91 | H16: 66 | I16: 67 | J16: 57 | K16: 70 | L16: =SUM(F16:K16) -> 397 | M16: =AVERAGE(F16:K16) -> 66.166667 | N16: {=_xlfn.IFS(M16>=70,"A",M16>=60,"B",M16>=50,"C",M16>=45,"D",M16>=40,"E",TRUE,"F")} -> B | O16: =COUNTIFS($D$2:$D$721,D16,$E$2:$E$721,E16,$M$2:$M$721,">"&M16)+1 -> 17
A17: STU006 | B17: John Anyanwu | C17: Male | D17: JSS1A | E17: First Term | F17: 65 | G17: 79 | H17: 75 | I17: 91 | J17: 80 | K17: 84 | L17: =SUM(F17:K17) -> 474 | M17: =AVERAGE(F17:K17) -> 79 | N17: {=_xlfn.IFS(M17>=70,"A",M17>=60,"B",M17>=50,"C",M17>=45,"D",M17>=40,"E",TRUE,"F")} -> A | O17: =COUNTIFS($D$2:$D$721,D17,$E$2:$E$721,E17,$M$2:$M$721,">"&M17)+1 -> 2
A18: STU006 | B18: John Anyanwu | C18: Male | D18: JSS1A | E18: Second Term | F18: 66 | G18: 68 | H18: 66 | I18: 80 | J18: 79 | K18: 71 | L18: =SUM(F18:K18) -> 430 | M18: =AVERAGE(F18:K18) -> 71.666667 | N18: {=_xlfn.IFS(M18>=70,"A",M18>=60,"B",M18>=50,"C",M18>=45,"D",M18>=40,"E",TRUE,"F")} -> A | O18: =COUNTIFS($D$2:$D$721,D18,$E$2:$E$721,E18,$M$2:$M$721,">"&M18)+1 -> 7
A19: STU006 | B19: John Anyanwu | C19: Male | D19: JSS1A | E19: Third Term | F19: 50 | H19: 70 | I19: 67 | J19: 80 | K19: 65 | L19: =SUM(F19:K19) -> 332 | M19: =AVERAGE(F19:K19) -> 66.4 | N19: {=_xlfn.IFS(M19>=70,"A",M19>=60,"B",M19>=50,"C",M19>=45,"D",M19>=40,"E",TRUE,"F")} -> B | O19: =COUNTIFS($D$2:$D$721,D19,$E$2:$E$721,E19,$M$2:$M$721,">"&M19)+1 -> 15 | Q19: STUDENT NAME | R19: CLASS | S19: AVERAGE | U19: STUDENT NAME | V19: CLASS | W19: AVERAGE
A20: STU007 | B20: Zainab Ogunleye | C20: Female | D20: JSS1A | E20: First Term | F20: 48 | G20: 36 | H20: 47 | I20: 54 | J20: 61 | K20: 71 | L20: =SUM(F20:K20) -> 317 | M20: =AVERAGE(F20:K20) -> 52.833333 | N20: {=_xlfn.IFS(M20>=70,"A",M20>=60,"B",M20>=50,"C",M20>=45,"D",M20>=40,"E",TRUE,"F")} -> C | O20: =COUNTIFS($D$2:$D$721,D20,$E$2:$E$721,E20,$M$2:$M$721,">"&M20)+1 -> 29 | Q20: Yetunde Adebayo | R20: Third Term | S20: 91 | U20: Ifeoma Lawal | V20: Third Term | W20: 88.7
A21: STU007 | B21: Zainab Ogunleye | C21: Female | D21: JSS1A | E21: Second Term | F21: 48 | G21: 64 | H21: 56 | I21: 64 | J21: 55 | K21: 69 | L21: =SUM(F21:K21) -> 356 | M21: =AVERAGE(F21:K21) -> 59.333333 | N21: {=_xlfn.IFS(M21>=70,"A",M21>=60,"B",M21>=50,"C",M21>=45,"D",M21>=40,"E",TRUE,"F")} -> C | O21: =COUNTIFS($D$2:$D$721,D21,$E$2:$E$721,E21,$M$2:$M$721,">"&M21)+1 -> 23 | Q21: Micheal Amadi | R21: Third Term | S21: 90.3 | U21: Peter Uzor | V21: Third Term | W21: 85.2
A22: STU007 | B22: Zainab Ogunleye | C22: Female | D22: JSS1A | E22: Third Term | F22: 41 | G22: 58 | H22: 46 | I22: 54 | J22: 48 | K22: 57 | L22: =SUM(F22:K22) -> 304 | M22: =AVERAGE(F22:K22) -> 50.666667 | N22: {=_xlfn.IFS(M22>=70,"A",M22>=60,"B",M22>=50,"C",M22>=45,"D",M22>=40,"E",TRUE,"F")} -> C | O22: =COUNTIFS($D$2:$D$721,D22,$E$2:$E$721,E22,$M$2:$M$721,">"&M22)+1 -> 35 | Q22: Peter Nwankwo | R22: Third Term | S22: 88.7 | U22: Tolu Mohammed | V22: Third Term | W22: 82
A23: STU008 | B23: Obiageli Umar | C23: Female | D23: JSS1A | E23: First Term | F23: 67 | G23: 70 | H23: 59 | I23: 84 | J23: 77 | K23: 84 | L23: =SUM(F23:K23) -> 441 | M23: =AVERAGE(F23:K23) -> 73.5 | N23: {=_xlfn.IFS(M23>=70,"A",M23>=60,"B",M23>=50,"C",M23>=45,"D",M23>=40,"E",TRUE,"F")} -> A | O23: =COUNTIFS($D$2:$D$721,D23,$E$2:$E$721,E23,$M$2:$M$721,">"&M23)+1 -> 7
A24: STU008 | B24: Obiageli Umar | C24: Female | D24: JSS1A | E24: Second Term | F24: 68 | G24: 64 | H24: 53 | I24: 65 | J24: 81 | K24: 67 | L24: =SUM(F24:K24) -> 398 | M24: =AVERAGE(F24:K24) -> 66.333333 | N24: {=_xlfn.IFS(M24>=70,"A",M24>=60,"B",M24>=50,"C",M24>=45,"D",M24>=40,"E",TRUE,"F")} -> B | O24: =COUNTIFS($D$2:$D$721,D24,$E$2:$E$721,E24,$M$2:$M$721,">"&M24)+1 -> 14
A25: STU008 | B25: Obiageli Umar | C25: Female | D25: JSS1A | E25: Third Term | F25: 67 | G25: 63 | H25: 68 | I25: 57 | J25: 79 | K25: 73 | L25: =SUM(F25:K25) -> 407 | M25: =AVERAGE(F25:K25) -> 67.833333 | N25: {=_xlfn.IFS(M25>=70,"A",M25>=60,"B",M25>=50,"C",M25>=45,"D",M25>=40,"E",TRUE,"F")} -> B | O25: =COUNTIFS($D$2:$D$721,D25,$E$2:$E$721,E25,$M$2:$M$721,">"&M25)+1 -> 14
A26: STU009 | B26: Nkechi Adebayo | C26: Female | D26: JSS1A | E26: First Term | F26: 55 | G26: 56 | H26: 59 | I26: 57 | J26: 64 | K26: 50 | L26: =SUM(F26:K26) -> 341 | M26: =AVERAGE(F26:K26) -> 56.833333 | N26: {=_xlfn.IFS(M26>=70,"A",M26>=60,"B",M26>=50,"C",M26>=45,"D",M26>=40,"E",TRUE,"F")} -> C | O26: =COUNTIFS($D$2:$D$721,D26,$E$2:$E$721,E26,$M$2:$M$721,">"&M26)+1 -> 24
A27: STU009 | B27: Nkechi Adebayo | C27: Female | D27: JSS1A | E27: Second Term | F27: 40 | G27: 59 | H27: 52 | I27: 55 | J27: 57 | K27: 63 | L27: =SUM(F27:K27) -> 326 | M27: =AVERAGE(F27:K27) -> 54.333333 | N27: {=_xlfn.IFS(M27>=70,"A",M27>=60,"B",M27>=50,"C",M27>=45,"D",M27>=40,"E",TRUE,"F")} -> C | O27: =COUNTIFS($D$2:$D$721,D27,$E$2:$E$721,E27,$M$2:$M$721,">"&M27)+1 -> 28
A28: STU009 | B28: Nkechi Adebayo | C28: Female | D28: JSS1A | E28: Third Term | F28: 43 | G28: 56 | H28: 44 | I28: 53 | J28: 64 | K28: 66 | L28: =SUM(F28:K28) -> 326 | M28: =AVERAGE(F28:K28) -> 54.333333 | N28: {=_xlfn.IFS(M28>=70,"A",M28>=60,"B",M28>=50,"C",M28>=45,"D",M28>=40,"E",TRUE,"F")} -> C | O28: =COUNTIFS($D$2:$D$721,D28,$E$2:$E$721,E28,$M$2:$M$721,">"&M28)+1 -> 31 | Q28: STUDENT NAME | R28: CLASS | S28: AVERAGE | U28: STUDENT NAME | V28: CLASS | W28: AVERAGE
A29: STU010 | B29: Olumide Umar | C29: Male | D29: JSS1A | E29: First Term | F29: 44 | G29: 63 | H29: 48 | I29: 66 | J29: 48 | K29: 56 | L29: =SUM(F29:K29) -> 325 | M29: =AVERAGE(F29:K29) -> 54.166667 | N29: {=_xlfn.IFS(M29>=70,"A",M29>=60,"B",M29>=50,"C",M29>=45,"D",M29>=40,"E",TRUE,"F")} -> C | O29: =COUNTIFS($D$2:$D$721,D29,$E$2:$E$721,E29,$M$2:$M$721,">"&M29)+1 -> 27 | Q29: Sade Umar | R29: Third Term | S29: 96.7 | U29: Tolu Williams | V29: Third Term | W29: 89.5
A30: STU010 | B30: Olumide Umar | C30: Male | D30: JSS1A | E30: Second Term | F30: 52 | G30: 60 | H30: 70 | I30: 71 | J30: 77 | K30: 76 | L30: =SUM(F30:K30) -> 406 | M30: =AVERAGE(F30:K30) -> 67.666667 | N30: {=_xlfn.IFS(M30>=70,"A",M30>=60,"B",M30>=50,"C",M30>=45,"D",M30>=40,"E",TRUE,"F")} -> B | O30: =COUNTIFS($D$2:$D$721,D30,$E$2:$E$721,E30,$M$2:$M$721,">"&M30)+1 -> 11 | Q30: Dare Musa | R30: Third Term | S30: 93.5 | U30: Daniel Oyewole | V30: Third Term | W30: 89.3
A31: STU010 | B31: Olumide Umar | C31: Male | D31: JSS1A | E31: Third Term | F31: 58 | G31: 64 | H31: 71 | I31: 69 | J31: 68 | K31: 62 | L31: =SUM(F31:K31) -> 392 | M31: =AVERAGE(F31:K31) -> 65.333333 | N31: {=_xlfn.IFS(M31>=70,"A",M31>=60,"B",M31>=50,"C",M31>=45,"D",M31>=40,"E",TRUE,"F")} -> B | O31: =COUNTIFS($D$2:$D$721,D31,$E$2:$E$721,E31,$M$2:$M$721,">"&M31)+1 -> 18 | Q31: Uchenna Nwosu | R31: Third Term | S31: 84 | U31: Daniel Nnadi | V31: Third Term | W31: 86
A32: STU011 | B32: Daniel Onyeka | C32: Male | D32: JSS1A | E32: First Term | F32: 37 | G32: 24 | H32: 39 | I32: 40 | J32: 53 | K32: 46 | L32: =SUM(F32:K32) -> 239 | M32: =AVERAGE(F32:K32) -> 39.833333 | N32: {=_xlfn.IFS(M32>=70,"A",M32>=60,"B",M32>=50,"C",M32>=45,"D",M32>=40,"E",TRUE,"F")} -> F | O32: =COUNTIFS($D$2:$D$721,D32,$E$2:$E$721,E32,$M$2:$M$721,">"&M32)+1 -> 40
A33: STU011 | B33: Daniel Onyeka | C33: Male | D33: JSS1A | E33: Second Term | F33: 41 | G33: 59 | H33: 40 | I33: 55 | J33: 41 | K33: 56 | L33: =SUM(F33:K33) -> 292 | M33: =AVERAGE(F33:K33) -> 48.666667 | N33: {=_xlfn.IFS(M33>=70,"A",M33>=60,"B",M33>=50,"C",M33>=45,"D",M33>=40,"E",TRUE,"F")} -> D | O33: =COUNTIFS($D$2:$D$721,D33,$E$2:$E$721,E33,$M$2:$M$721,">"&M33)+1 -> 35
A34: STU011 | B34: Daniel Onyeka | C34: Male | D34: JSS1A | E34: Third Term | F34: 53 | G34: 62 | I34: 61 | J34: 62 | K34: 62 | L34: =SUM(F34:K34) -> 300 | M34: =AVERAGE(F34:K34) -> 60 | N34: {=_xlfn.IFS(M34>=70,"A",M34>=60,"B",M34>=50,"C",M34>=45,"D",M34>=40,"E",TRUE,"F")} -> B | O34: =COUNTIFS($D$2:$D$721,D34,$E$2:$E$721,E34,$M$2:$M$721,">"&M34)+1 -> 25
A35: STU012 | B35: Daniel Kalu | C35: Male | D35: JSS1A | E35: Third Term | F35: 63 | G35: 74 | H35: 70 | I35: 79 | J35: 77 | K35: 80 | L35: =SUM(F35:K35) -> 443 | M35: =AVERAGE(F35:K35) -> 73.833333 | N35: {=_xlfn.IFS(M35>=70,"A",M35>=60,"B",M35>=50,"C",M35>=45,"D",M35>=40,"E",TRUE,"F")} -> A | O35: =COUNTIFS($D$2:$D$721,D35,$E$2:$E$721,E35,$M$2:$M$721,">"&M35)+1 -> 6
A36: STU012 | B36: Daniel Kalu | C36: Male | D36: JSS1A | E36: First Term | F36: 63 | G36: 71 | H36: 69 | I36: 64 | J36: 63 | K36: 91 | L36: =SUM(F36:K36) -> 421 | M36: =AVERAGE(F36:K36) -> 70.166667 | N36: {=_xlfn.IFS(M36>=70,"A",M36>=60,"B",M36>=50,"C",M36>=45,"D",M36>=40,"E",TRUE,"F")} -> A | O36: =COUNTIFS($D$2:$D$721,D36,$E$2:$E$721,E36,$M$2:$M$721,">"&M36)+1 -> 9
A37: STU012 | B37: Daniel Kalu | C37: Male | D37: JSS1A | E37: Second Term | F37: 79 | G37: 62 | H37: 73 | I37: 79 | J37: 81 | K37: 79 | L37: =SUM(F37:K37) -> 453 | M37: =AVERAGE(F37:K37) -> 75.5 | N37: {=_xlfn.IFS(M37>=70,"A",M37>=60,"B",M37>=50,"C",M37>=45,"D",M37>=40,"E",TRUE,"F")} -> A | O37: =COUNTIFS($D$2:$D$721,D37,$E$2:$E$721,E37,$M$2:$M$721,">"&M37)+1 -> 6
A38: STU013 | B38: Sani Adewale | C38: Male | D38: JSS1A | E38: First Term | F38: 69 | G38: 76 | H38: 58 | I38: 68 | J38: 66 | K38: 82 | L38: =SUM(F38:K38) -> 419 | M38: =AVERAGE(F38:K38) -> 69.833333 | N38: {=_xlfn.IFS(M38>=70,"A",M38>=60,"B",M38>=50,"C",M38>=45,"D",M38>=40,"E",TRUE,"F")} -> B | O38: =COUNTIFS($D$2:$D$721,D38,$E$2:$E$721,E38,$M$2:$M$721,">"&M38)+1 -> 10
A39: STU013 | B39: Sani Adewale | C39: Male | D39: JSS1A | E39: Second Term | F39: 61 | G39: 78 | H39: 62 | I39: 71 | J39: 62 | K39: 83 | L39: =SUM(F39:K39) -> 417 | M39: =AVERAGE(F39:K39) -> 69.5 | N39: {=_xlfn.IFS(M39>=70,"A",M39>=60,"B",M39>=50,"C",M39>=45,"D",M39>=40,"E",TRUE,"F")} -> B | O39: =COUNTIFS($D$2:$D$721,D39,$E$2:$E$721,E39,$M$2:$M$721,">"&M39)+1 -> 10
A40: STU013 | B40: Sani Adewale | C40: Male | D40: JSS1A | E40: Third Term | F40: 58 | G40: 57 | H40: 61 | I40: 54 | J40: 71 | K40: 74 | L40: =SUM(F40:K40) -> 375 | M40: =AVERAGE(F40:K40) -> 62.5 | N40: {=_xlfn.IFS(M40>=70,"A",M40>=60,"B",M40>=50,"C",M40>=45,"D",M40>=40,"E",TRUE,"F")} -> B | O40: =COUNTIFS($D$2:$D$721,D40,$E$2:$E$721,E40,$M$2:$M$721,">"&M40)+1 -> 23
...

Sheet Class Summary 
A1: CLASS | B1: TERM | C1: STUDENTS | D1: AVERAGE | E1: PASS RATE | G1: CLASS | H1: THIRD TERM PASS RATE
A2: JSS1A | B2: First Term | C2: =COUNTIFS('Cleaned Data'!$D$2:$D$721,A2,'Cleaned Data'!$E$2:$E$721,B2) -> 40 | D2: =AVERAGEIFS('Cleaned Data'!$M$2:$M$721,'Cleaned Data'!$D$2:$D$721,A2,'Cleaned Data'!$E$2:$E$721,B2) -> 60.008333 | E2: =IF(C2=0,0,COUNTIFS('Cleaned Data'!$D$2:$D$721,A2,'Cleaned Data'!$E$2:$E$721,B2,'Cleaned Data'!$M$2:$M$721,">=50")/C2) -> 0.775 | G2: JSS1A | H2: 0.9
A3: JSS1A | B3: Second Term | C3: =COUNTIFS('Cleaned Data'!$D$2:$D$721,A3,'Cleaned Data'!$E$2:$E$721,B3) -> 40 | D3: =AVERAGEIFS('Cleaned Data'!$M$2:$M$721,'Cleaned Data'!$D$2:$D$721,A3,'Cleaned Data'!$E$2:$E$721,B3) -> 61.95 | E3: =IF(C3=0,0,COUNTIFS('Cleaned Data'!$D$2:$D$721,A3,'Cleaned Data'!$E$2:$E$721,B3,'Cleaned Data'!$M$2:$M$721,">=50")/C3) -> 0.825 | G3: JSS1B | H3: 0.9
A4: JSS1A | B4: Third Term | C4: =COUNTIFS('Cleaned Data'!$D$2:$D$721,A4,'Cleaned Data'!$E$2:$E$721,B4) -> 40 | D4: =AVERAGEIFS('Cleaned Data'!$M$2:$M$721,'Cleaned Data'!$D$2:$D$721,A4,'Cleaned Data'!$E$2:$E$721,B4) -> 63.168333 | E4: =IF(C4=0,0,COUNTIFS('Cleaned Data'!$D$2:$D$721,A4,'Cleaned Data'!$E$2:$E$721,B4,'Cleaned Data'!$M$2:$M$721,">=50")/C4) -> 0.9 | G4: JSS2A | H4: 0.85 | M4: Average of AVERAGE | N4: Column Labels
A5: JSS1B | B5: First Term | C5: =COUNTIFS('Cleaned Data'!$D$2:$D$721,A5,'Cleaned Data'!$E$2:$E$721,B5) -> 40 | D5: =AVERAGEIFS('Cleaned Data'!$M$2:$M$721,'Cleaned Data'!$D$2:$D$721,A5,'Cleaned Data'!$E$2:$E$721,B5) -> 59.189583 | E5: =IF(C5=0,0,COUNTIFS('Cleaned Data'!$D$2:$D$721,A5,'Cleaned Data'!$E$2:$E$721,B5,'Cleaned Data'!$M$2:$M$721,">=50")/C5) -> 0.9 | G5: JSS2B | H5: 0.85 | M5: Row Labels | N5: First Term | O5: Second Term | P5: Third Term | Q5: Grand Total
A6: JSS1B | B6: Second Term | C6: =COUNTIFS('Cleaned Data'!$D$2:$D$721,A6,'Cleaned Data'!$E$2:$E$721,B6) -> 40 | D6: =AVERAGEIFS('Cleaned Data'!$M$2:$M$721,'Cleaned Data'!$D$2:$D$721,A6,'Cleaned Data'!$E$2:$E$721,B6) -> 61.691667 | E6: =IF(C6=0,0,COUNTIFS('Cleaned Data'!$D$2:$D$721,A6,'Cleaned Data'!$E$2:$E$721,B6,'Cleaned Data'!$M$2:$M$721,">=50")/C6) -> 0.9 | G6: JSS3A | H6: 0.8 | M6: JSS1A | N6: 60.008333 | O6: 61.95 | P6: 63.168333 | Q6: 61.708889
A7: JSS1B | B7: Third Term | C7: =COUNTIFS('Cleaned Data'!$D$2:$D$721,A7,'Cleaned Data'!$E$2:$E$721,B7) -> 40 | D7: =AVERAGEIFS('Cleaned Data'!$M$2:$M$721,'Cleaned Data'!$D$2:$D$721,A7,'Cleaned Data'!$E$2:$E$721,B7) -> 63.54 | E7: =IF(C7=0,0,COUNTIFS('Cleaned Data'!$D$2:$D$721,A7,'Cleaned Data'!$E$2:$E$721,B7,'Cleaned Data'!$M$2:$M$721,">=50")/C7) -> 0.9 | G7: JSS3B | H7: 0.9 | M7: JSS1B | N7: 59.189583 | O7: 61.691667 | P7: 63.54 | Q7: 61.47375
A8: JSS2A | B8: First Term | C8: =COUNTIFS('Cleaned Data'!$D$2:$D$721,A8,'Cleaned Data'!$E$2:$E$721,B8) -> 40 | D8: =AVERAGEIFS('Cleaned Data'!$M$2:$M$721,'Cleaned Data'!$D$2:$D$721,A8,'Cleaned Data'!$E$2:$E$721,B8) -> 61.479167 | E8: =IF(C8=0,0,COUNTIFS('Cleaned Data'!$D$2:$D$721,A8,'Cleaned Data'!$E$2:$E$721,B8,'Cleaned Data'!$M$2:$M$721,">=50")/C8) -> 0.775 | M8: JSS2A | N8: 61.479167 | O8: 64.299167 | P8: 65.5625 | Q8: 63.780278
A9: JSS2A | B9: Second Term | C9: =COUNTIFS('Cleaned Data'!$D$2:$D$721,A9,'Cleaned Data'!$E$2:$E$721,B9) -> 40 | D9: =AVERAGEIFS('Cleaned Data'!$M$2:$M$721,'Cleaned Data'!$D$2:$D$721,A9,'Cleaned Data'!$E$2:$E$721,B9) -> 64.299167 | E9: =IF(C9=0,0,COUNTIFS('Cleaned Data'!$D$2:$D$721,A9,'Cleaned Data'!$E$2:$E$721,B9,'Cleaned Data'!$M$2:$M$721,">=50")/C9) -> 0.875 | M9: JSS2B | N9: 61.579167 | O9: 63.541667 | P9: 64.925 | Q9: 63.348611
A10: JSS2A | B10: Third Term | C10: =COUNTIFS('Cleaned Data'!$D$2:$D$721,A10,'Cleaned Data'!$E$2:$E$721,B10) -> 40 | D10: =AVERAGEIFS('Cleaned Data'!$M$2:$M$721,'Cleaned Data'!$D$2:$D$721,A10,'Cleaned Data'!$E$2:$E$721,B10) -> 65.5625 | E10: =IF(C10=0,0,COUNTIFS('Cleaned Data'!$D$2:$D$721,A10,'Cleaned Data'!$E$2:$E$721,B10,'Cleaned Data'!$M$2:$M$721,">=50")/C10) -> 0.85 | M10: JSS3A | N10: 57.6625 | O10: 59.975 | P10: 62.65 | Q10: 60.095833
A11: JSS2B | B11: First Term | C11: =COUNTIFS('Cleaned Data'!$D$2:$D$721,A11,'Cleaned Data'!$E$2:$E$721,B11) -> 40 | D11: =AVERAGEIFS('Cleaned Data'!$M$2:$M$721,'Cleaned Data'!$D$2:$D$721,A11,'Cleaned Data'!$E$2:$E$721,B11) -> 61.579167 | E11: =IF(C11=0,0,COUNTIFS('Cleaned Data'!$D$2:$D$721,A11,'Cleaned Data'!$E$2:$E$721,B11,'Cleaned Data'!$M$2:$M$721,">=50")/C11) -> 0.825 | M11: JSS3B | N11: 60.675 | O11: 63.465833 | P11: 66.725 | Q11: 63.621944
A12: JSS2B | B12: Second Term | C12: =COUNTIFS('Cleaned Data'!$D$2:$D$721,A12,'Cleaned Data'!$E$2:$E$721,B12) -> 40 | D12: =AVERAGEIFS('Cleaned Data'!$M$2:$M$721,'Cleaned Data'!$D$2:$D$721,A12,'Cleaned Data'!$E$2:$E$721,B12) -> 63.541667 | E12: =IF(C12=0,0,COUNTIFS('Cleaned Data'!$D$2:$D$721,A12,'Cleaned Data'!$E$2:$E$721,B12,'Cleaned Data'!$M$2:$M$721,">=50")/C12) -> 0.875 | M12: Grand Total | N12: 60.098958 | O12: 62.487222 | P12: 64.428472 | Q12: 62.338218
A13: JSS2B | B13: Third Term | C13: =COUNTIFS('Cleaned Data'!$D$2:$D$721,A13,'Cleaned Data'!$E$2:$E$721,B13) -> 40 | D13: =AVERAGEIFS('Cleaned Data'!$M$2:$M$721,'Cleaned Data'!$D$2:$D$721,A13,'Cleaned Data'!$E$2:$E$721,B13) -> 64.925 | E13: =IF(C13=0,0,COUNTIFS('Cleaned Data'!$D$2:$D$721,A13,'Cleaned Data'!$E$2:$E$721,B13,'Cleaned Data'!$M$2:$M$721,">=50")/C13) -> 0.85
A14: JSS3A | B14: First Term | C14: =COUNTIFS('Cleaned Data'!$D$2:$D$721,A14,'Cleaned Data'!$E$2:$E$721,B14) -> 40 | D14: =AVERAGEIFS('Cleaned Data'!$M$2:$M$721,'Cleaned Data'!$D$2:$D$721,A14,'Cleaned Data'!$E$2:$E$721,B14) -> 57.6625 | E14: =IF(C14=0,0,COUNTIFS('Cleaned Data'!$D$2:$D$721,A14,'Cleaned Data'!$E$2:$E$721,B14,'Cleaned Data'!$M$2:$M$721,">=50")/C14) -> 0.75
A15: JSS3A | B15: Second Term | C15: =COUNTIFS('Cleaned Data'!$D$2:$D$721,A15,'Cleaned Data'!$E$2:$E$721,B15) -> 40 | D15: =AVERAGEIFS('Cleaned Data'!$M$2:$M$721,'Cleaned Data'!$D$2:$D$721,A15,'Cleaned Data'!$E$2:$E$721,B15) -> 59.975 | E15: =IF(C15=0,0,COUNTIFS('Cleaned Data'!$D$2:$D$721,A15,'Cleaned Data'!$E$2:$E$721,B15,'Cleaned Data'!$M$2:$M$721,">=50")/C15) -> 0.825
A16: JSS3A | B16: Third Term | C16: =COUNTIFS('Cleaned Data'!$D$2:$D$721,A16,'Cleaned Data'!$E$2:$E$721,B16) -> 40 | D16: =AVERAGEIFS('Cleaned Data'!$M$2:$M$721,'Cleaned Data'!$D$2:$D$721,A16,'Cleaned Data'!$E$2:$E$721,B16) -> 62.65 | E16: =IF(C16=0,0,COUNTIFS('Cleaned Data'!$D$2:$D$721,A16,'Cleaned Data'!$E$2:$E$721,B16,'Cleaned Data'!$M$2:$M$721,">=50")/C16) -> 0.8
A17: JSS3B | B17: First Term | C17: =COUNTIFS('Cleaned Data'!$D$2:$D$721,A17,'Cleaned Data'!$E$2:$E$721,B17) -> 40 | D17: =AVERAGEIFS('Cleaned Data'!$M$2:$M$721,'Cleaned Data'!$D$2:$D$721,A17,'Cleaned Data'!$E$2:$E$721,B17) -> 60.675 | E17: =IF(C17=0,0,COUNTIFS('Cleaned Data'!$D$2:$D$721,A17,'Cleaned Data'!$E$2:$E$721,B17,'Cleaned Data'!$M$2:$M$721,">=50")/C17) -> 0.85
A18: JSS3B | B18: Second Term | C18: =COUNTIFS('Cleaned Data'!$D$2:$D$721,A18,'Cleaned Data'!$E$2:$E$721,B18) -> 40 | D18: =AVERAGEIFS('Cleaned Data'!$M$2:$M$721,'Cleaned Data'!$D$2:$D$721,A18,'Cleaned Data'!$E$2:$E$721,B18) -> 63.465833 | E18: =IF(C18=0,0,COUNTIFS('Cleaned Data'!$D$2:$D$721,A18,'Cleaned Data'!$E$2:$E$721,B18,'Cleaned Data'!$M$2:$M$721,">=50")/C18) -> 0.9
A19: JSS3B | B19: Third Term | C19: =COUNTIFS('Cleaned Data'!$D$2:$D$721,A19,'Cleaned Data'!$E$2:$E$721,B19) -> 40 | D19: =AVERAGEIFS('Cleaned Data'!$M$2:$M$721,'Cleaned Data'!$D$2:$D$721,A19,'Cleaned Data'!$E$2:$E$721,B19) -> 66.725 | E19: =IF(C19=0,0,COUNTIFS('Cleaned Data'!$D$2:$D$721,A19,'Cleaned Data'!$E$2:$E$721,B19,'Cleaned Data'!$M$2:$M$721,">=50")/C19) -> 0.9

Sheet Subjects
A1: SUBJECT | B1: ALL TERMS AVERAGE | C1: FIRST TERM | D1: SECOND TERM | E1: THIRD TERM
A2: MATHS | B2: =AVERAGE('Cleaned Data'!$F$2:$F$721) -> 55.414465 | C2: =AVERAGEIFS('Cleaned Data'!$F$2:$F$721,'Cleaned Data'!$E$2:$E$721,C$1) -> 53.175 | D2: =AVERAGEIFS('Cleaned Data'!$F$2:$F$721,'Cleaned Data'!$E$2:$E$721,D$1) -> 55.661088 | E2: =AVERAGEIFS('Cleaned Data'!$F$2:$F$721,'Cleaned Data'!$E$2:$E$721,E$1) -> 57.408333
A3: ENGLISH | B3: =AVERAGE('Cleaned Data'!$G$2:$G$721) -> 61.453911 | C3: =AVERAGEIFS('Cleaned Data'!$G$2:$G$721,'Cleaned Data'!$E$2:$E$721,C$1) -> 59.3125 | D3: =AVERAGEIFS('Cleaned Data'!$G$2:$G$721,'Cleaned Data'!$E$2:$E$721,D$1) -> 61.260504 | E3: =AVERAGEIFS('Cleaned Data'!$G$2:$G$721,'Cleaned Data'!$E$2:$E$721,E$1) -> 63.806723
A4: BASIC SCIENCE | B4: =AVERAGE('Cleaned Data'!$H$2:$H$721) -> 59.437151 | C4: =AVERAGEIFS('Cleaned Data'!$H$2:$H$721,'Cleaned Data'!$E$2:$E$721,C$1) -> 56.87395 | D4: =AVERAGEIFS('Cleaned Data'!$H$2:$H$721,'Cleaned Data'!$E$2:$E$721,D$1) -> 59.65272 | E4: =AVERAGEIFS('Cleaned Data'!$H$2:$H$721,'Cleaned Data'!$E$2:$E$721,E$1) -> 61.774059 | J4: Row Labels | K4: Sum of ALL TERMS AVERAGE
A5: SOCIAL STUDIES | B5: =AVERAGE('Cleaned Data'!$I$2:$I$721) -> 64.763561 | C5: =AVERAGEIFS('Cleaned Data'!$I$2:$I$721,'Cleaned Data'!$E$2:$E$721,C$1) -> 63.012552 | D5: =AVERAGEIFS('Cleaned Data'!$I$2:$I$721,'Cleaned Data'!$E$2:$E$721,D$1) -> 65.125 | E5: =AVERAGEIFS('Cleaned Data'!$I$2:$I$721,'Cleaned Data'!$E$2:$E$721,E$1) -> 66.145833 | J5: MATHS | K5: 55.414465
A6: COMPUTER SCIENCE | B6: =AVERAGE('Cleaned Data'!$J$2:$J$721) -> 65.607242 | C6: =AVERAGEIFS('Cleaned Data'!$J$2:$J$721,'Cleaned Data'!$E$2:$E$721,C$1) -> 63.302521 | D6: =AVERAGEIFS('Cleaned Data'!$J$2:$J$721,'Cleaned Data'!$E$2:$E$721,D$1) -> 65.433333 | E6: =AVERAGEIFS('Cleaned Data'!$J$2:$J$721,'Cleaned Data'!$E$2:$E$721,E$1) -> 68.066667 | J6: BASIC SCIENCE | K6: 59.437151
A7: CIVIC EDUCATION | B7: =AVERAGE('Cleaned Data'!$K$2:$K$721) -> 67.319444 | C7: =AVERAGEIFS('Cleaned Data'!$K$2:$K$721,'Cleaned Data'!$E$2:$E$721,C$1) -> 65.0375 | D7: =AVERAGEIFS('Cleaned Data'!$K$2:$K$721,'Cleaned Data'!$E$2:$E$721,D$1) -> 67.6125 | E7: =AVERAGEIFS('Cleaned Data'!$K$2:$K$721,'Cleaned Data'!$E$2:$E$721,E$1) -> 69.308333 | J7: ENGLISH | K7: 61.453911
J8: SOCIAL STUDIES | K8: 64.763561
J9: COMPUTER SCIENCE | K9: 65.607242
J10: CIVIC EDUCATION | K10: 67.319444
J11: Grand Total | K11: 373.99577
A14: Term | B14: Second Term
A16: Row Labels | B16: Average of Civic Education | C16: Average of Computer Studies | D16: Average of Basic Science | E16: Average of Social Studies | F16: Average of Maths | G16: Average of English
A17: JSS1A | B17: 66.375 | C17: 65.5 | D17: 59.1 | E17: 65.725 | F17: 53.525 | G17: 61.475
A18: Grand Total | B18: 66.375 | C18: 65.5 | D18: 59.1 | E18: 65.725 | F18: 53.525 | G18: 61.475

Sheet Improvement
A1: STUDENT ID | B1: STUDENT NAME | C1: FIRST TERM | D1: THIRD TERM | E1: CHANGE | F1: STATUS | H1: CLASS | I1: FIRST TERM | J1: THIRD TERM | K1: IMPROVEMENT
A2: STU001 | B2: =_xlfn.XLOOKUP(A2,'Cleaned Data'!$A$2:$A$721,'Cleaned Data'!$B$2:$B$721) -> John Danjuma | C2: =AVERAGEIFS('Cleaned Data'!$M$2:$M$721,'Cleaned Data'!$A$2:$A$721,A2,'Cleaned Data'!$E$2:$E$721,"First Term") -> 79 | D2: =AVERAGEIFS('Cleaned Data'!$M$2:$M$721,'Cleaned Data'!$A$2:$A$721,A2,'Cleaned Data'!$E$2:$E$721,"Third Term") -> 72.166667 | E2: =D2-C2 -> -6.8333333 | F2: =IF(E2>0,"Improved",IF(E2<0,"Dropped","Unchanged")) -> Dropped | H2: JSS1A | I2: =AVERAGEIFS('Cleaned Data'!$M$2:$M$721,'Cleaned Data'!$D$2:$D$721,H2,'Cleaned Data'!$E$2:$E$721,"First Term") -> 60.008333 | J2: =AVERAGEIFS('Cleaned Data'!$M$2:$M$721,'Cleaned Data'!$D$2:$D$721,H2,'Cleaned Data'!$E$2:$E$721,"Third Term") -> 63.168333 | K2: =J2-I2 -> 3.16
A3: STU002 | B3: =_xlfn.XLOOKUP(A3,'Cleaned Data'!$A$2:$A$721,'Cleaned Data'!$B$2:$B$721) -> Damilola Danjuma | C3: =AVERAGEIFS('Cleaned Data'!$M$2:$M$721,'Cleaned Data'!$A$2:$A$721,A3,'Cleaned Data'!$E$2:$E$721,"First Term") -> 47.166667 | D3: =AVERAGEIFS('Cleaned Data'!$M$2:$M$721,'Cleaned Data'!$A$2:$A$721,A3,'Cleaned Data'!$E$2:$E$721,"Third Term") -> 49 | E3: =D3-C3 -> 1.8333333 | F3: =IF(E3>0,"Improved",IF(E3<0,"Dropped","Unchanged")) -> Improved | H3: JSS1B | I3: =AVERAGEIFS('Cleaned Data'!$M$2:$M$721,'Cleaned Data'!$D$2:$D$721,H3,'Cleaned Data'!$E$2:$E$721,"First Term") -> 59.189583 | J3: =AVERAGEIFS('Cleaned Data'!$M$2:$M$721,'Cleaned Data'!$D$2:$D$721,H3,'Cleaned Data'!$E$2:$E$721,"Third Term") -> 63.54 | K3: =J3-I3 -> 4.3504167
A4: STU003 | B4: =_xlfn.XLOOKUP(A4,'Cleaned Data'!$A$2:$A$721,'Cleaned Data'!$B$2:$B$721) -> Khadija Johnson | C4: =AVERAGEIFS('Cleaned Data'!$M$2:$M$721,'Cleaned Data'!$A$2:$A$721,A4,'Cleaned Data'!$E$2:$E$721,"First Term") -> 70.5 | D4: =AVERAGEIFS('Cleaned Data'!$M$2:$M$721,'Cleaned Data'!$A$2:$A$721,A4,'Cleaned Data'!$E$2:$E$721,"Third Term") -> 59.833333 | E4: =D4-C4 -> -10.666667 | F4: =IF(E4>0,"Improved",IF(E4<0,"Dropped","Unchanged")) -> Dropped | H4: JSS2A | I4: =AVERAGEIFS('Cleaned Data'!$M$2:$M$721,'Cleaned Data'!$D$2:$D$721,H4,'Cleaned Data'!$E$2:$E$721,"First Term") -> 61.479167 | J4: =AVERAGEIFS('Cleaned Data'!$M$2:$M$721,'Cleaned Data'!$D$2:$D$721,H4,'Cleaned Data'!$E$2:$E$721,"Third Term") -> 65.5625 | K4: =J4-I4 -> 4.0833333
A5: STU004 | B5: =_xlfn.XLOOKUP(A5,'Cleaned Data'!$A$2:$A$721,'Cleaned Data'!$B$2:$B$721) -> Favour Yakubu | C5: =AVERAGEIFS('Cleaned Data'!$M$2:$M$721,'Cleaned Data'!$A$2:$A$721,A5,'Cleaned Data'!$E$2:$E$721,"First Term") -> 76.5 | D5: =AVERAGEIFS('Cleaned Data'!$M$2:$M$721,'Cleaned Data'!$A$2:$A$721,A5,'Cleaned Data'!$E$2:$E$721,"Third Term") -> 76.833333 | E5: =D5-C5 -> 0.33333333 | F5: =IF(E5>0,"Improved",IF(E5<0,"Dropped","Unchanged")) -> Improved | H5: JSS2B | I5: =AVERAGEIFS('Cleaned Data'!$M$2:$M$721,'Cleaned Data'!$D$2:$D$721,H5,'Cleaned Data'!$E$2:$E$721,"First Term") -> 61.579167 | J5: =AVERAGEIFS('Cleaned Data'!$M$2:$M$721,'Cleaned Data'!$D$2:$D$721,H5,'Cleaned Data'!$E$2:$E$721,"Third Term") -> 64.925 | K5: =J5-I5 -> 3.3458333
A6: STU005 | B6: =_xlfn.XLOOKUP(A6,'Cleaned Data'!$A$2:$A$721,'Cleaned Data'!$B$2:$B$721) -> Emeka Olawale | C6: =AVERAGEIFS('Cleaned Data'!$M$2:$M$721,'Cleaned Data'!$A$2:$A$721,A6,'Cleaned Data'!$E$2:$E$721,"First Term") -> 63.5 | D6: =AVERAGEIFS('Cleaned Data'!$M$2:$M$721,'Cleaned Data'!$A$2:$A$721,A6,'Cleaned Data'!$E$2:$E$721,"Third Term") -> 66.166667 | E6: =D6-C6 -> 2.6666667 | F6: =IF(E6>0,"Improved",IF(E6<0,"Dropped","Unchanged")) -> Improved | H6: JSS3A | I6: =AVERAGEIFS('Cleaned Data'!$M$2:$M$721,'Cleaned Data'!$D$2:$D$721,H6,'Cleaned Data'!$E$2:$E$721,"First Term") -> 57.6625 | J6: =AVERAGEIFS('Cleaned Data'!$M$2:$M$721,'Cleaned Data'!$D$2:$D$721,H6,'Cleaned Data'!$E$2:$E$721,"Third Term") -> 62.65 | K6: =J6-I6 -> 4.9875
A7: STU006 | B7: =_xlfn.XLOOKUP(A7,'Cleaned Data'!$A$2:$A$721,'Cleaned Data'!$B$2:$B$721) -> John Anyanwu | C7: =AVERAGEIFS('Cleaned Data'!$M$2:$M$721,'Cleaned Data'!$A$2:$A$721,A7,'Cleaned Data'!$E$2:$E$721,"First Term") -> 79 | D7: =AVERAGEIFS('Cleaned Data'!$M$2:$M$721,'Cleaned Data'!$A$2:$A$721,A7,'Cleaned Data'!$E$2:$E$721,"Third Term") -> 66.4 | E7: =D7-C7 -> -12.6 | F7: =IF(E7>0,"Improved",IF(E7<0,"Dropped","Unchanged")) -> Dropped | H7: JSS3B | I7: =AVERAGEIFS('Cleaned Data'!$M$2:$M$721,'Cleaned Data'!$D$2:$D$721,H7,'Cleaned Data'!$E$2:$E$721,"First Term") -> 60.675 | J7: =AVERAGEIFS('Cleaned Data'!$M$2:$M$721,'Cleaned Data'!$D$2:$D$721,H7,'Cleaned Data'!$E$2:$E$721,"Third Term") -> 66.725 | K7: =J7-I7 -> 6.05
A8: STU007 | B8: =_xlfn.XLOOKUP(A8,'Cleaned Data'!$A$2:$A$721,'Cleaned Data'!$B$2:$B$721) -> Zainab Ogunleye | C8: =AVERAGEIFS('Cleaned Data'!$M$2:$M$721,'Cleaned Data'!$A$2:$A$721,A8,'Cleaned Data'!$E$2:$E$721,"First Term") -> 52.833333 | D8: =AVERAGEIFS('Cleaned Data'!$M$2:$M$721,'Cleaned Data'!$A$2:$A$721,A8,'Cleaned Data'!$E$2:$E$721,"Third Term") -> 50.666667 | E8: =D8-C8 -> -2.1666667 | F8: =IF(E8>0,"Improved",IF(E8<0,"Dropped","Unchanged")) -> Dropped
A9: STU008 | B9: =_xlfn.XLOOKUP(A9,'Cleaned Data'!$A$2:$A$721,'Cleaned Data'!$B$2:$B$721) -> Obiageli Umar | C9: =AVERAGEIFS('Cleaned Data'!$M$2:$M$721,'Cleaned Data'!$A$2:$A$721,A9,'Cleaned Data'!$E$2:$E$721,"First Term") -> 73.5 | D9: =AVERAGEIFS('Cleaned Data'!$M$2:$M$721,'Cleaned Data'!$A$2:$A$721,A9,'Cleaned Data'!$E$2:$E$721,"Third Term") -> 67.833333 | E9: =D9-C9 -> -5.6666667 | F9: =IF(E9>0,"Improved",IF(E9<0,"Dropped","Unchanged")) -> Dropped
A10: STU009 | B10: =_xlfn.XLOOKUP(A10,'Cleaned Data'!$A$2:$A$721,'Cleaned Data'!$B$2:$B$721) -> Nkechi Adebayo | C10: =AVERAGEIFS('Cleaned Data'!$M$2:$M$721,'Cleaned Data'!$A$2:$A$721,A10,'Cleaned Data'!$E$2:$E$721,"First Term") -> 56.833333 | D10: =AVERAGEIFS('Cleaned Data'!$M$2:$M$721,'Cleaned Data'!$A$2:$A$721,A10,'Cleaned Data'!$E$2:$E$721,"Third Term") -> 54.333333 | E10: =D10-C10 -> -2.5 | F10: =IF(E10>0,"Improved",IF(E10<0,"Dropped","Unchanged")) -> Dropped
A11: STU010 | B11: =_xlfn.XLOOKUP(A11,'Cleaned Data'!$A$2:$A$721,'Cleaned Data'!$B$2:$B$721) -> Olumide Umar | C11: =AVERAGEIFS('Cleaned Data'!$M$2:$M$721,'Cleaned Data'!$A$2:$A$721,A11,'Cleaned Data'!$E$2:$E$721,"First Term") -> 54.166667 | D11: =AVERAGEIFS('Cleaned Data'!$M$2:$M$721,'Cleaned Data'!$A$2:$A$721,A11,'Cleaned Data'!$E$2:$E$721,"Third Term") -> 65.333333 | E11: =D11-C11 -> 11.166667 | F11: =IF(E11>0,"Improved",IF(E11<0,"Dropped","Unchanged")) -> Improved
A12: STU011 | B12: =_xlfn.XLOOKUP(A12,'Cleaned Data'!$A$2:$A$721,'Cleaned Data'!$B$2:$B$721) -> Daniel Onyeka | C12: =AVERAGEIFS('Cleaned Data'!$M$2:$M$721,'Cleaned Data'!$A$2:$A$721,A12,'Cleaned Data'!$E$2:$E$721,"First Term") -> 39.833333 | D12: =AVERAGEIFS('Cleaned Data'!$M$2:$M$721,'Cleaned Data'!$A$2:$A$721,A12,'Cleaned Data'!$E$2:$E$721,"Third Term") -> 60 | E12: =D12-C12 -> 20.166667 | F12: =IF(E12>0,"Improved",IF(E12<0,"Dropped","Unchanged")) -> Improved
A13: STU012 | B13: =_xlfn.XLOOKUP(A13,'Cleaned Data'!$A$2:$A$721,'Cleaned Data'!$B$2:$B$721) -> Daniel Kalu | C13: =AVERAGEIFS('Cleaned Data'!$M$2:$M$721,'Cleaned Data'!$A$2:$A$721,A13,'Cleaned Data'!$E$2:$E$721,"First Term") -> 70.166667 | D13: =AVERAGEIFS('Cleaned Data'!$M$2:$M$721,'Cleaned Data'!$A$2:$A$721,A13,'Cleaned Data'!$E$2:$E$721,"Third Term") -> 73.833333 | E13: =D13-C13 -> 3.6666667 | F13: =IF(E13>0,"Improved",IF(E13<0,"Dropped","Unchanged")) -> Improved
A14: STU013 | B14: =_xlfn.XLOOKUP(A14,'Cleaned Data'!$A$2:$A$721,'Cleaned Data'!$B$2:$B$721) -> Sani Adewale | C14: =AVERAGEIFS('Cleaned Data'!$M$2:$M$721,'Cleaned Data'!$A$2:$A$721,A14,'Cleaned Data'!$E$2:$E$721,"First Term") -> 69.833333 | D14: =AVERAGEIFS('Cleaned Data'!$M$2:$M$721,'Cleaned Data'!$A$2:$A$721,A14,'Cleaned Data'!$E$2:$E$721,"Third Term") -> 62.5 | E14: =D14-C14 -> -7.3333333 | F14: =IF(E14>0,"Improved",IF(E14<0,"Dropped","Unchanged")) -> Dropped
A15: STU014 | B15: =_xlfn.XLOOKUP(A15,'Cleaned Data'!$A$2:$A$721,'Cleaned Data'!$B$2:$B$721) -> Uchenna Ogundipe | C15: =AVERAGEIFS('Cleaned Data'!$M$2:$M$721,'Cleaned Data'!$A$2:$A$721,A15,'Cleaned Data'!$E$2:$E$721,"First Term") -> 59.166667 | D15: =AVERAGEIFS('Cleaned Data'!$M$2:$M$721,'Cleaned Data'!$A$2:$A$721,A15,'Cleaned Data'!$E$2:$E$721,"Third Term") -> 57 | E15: =D15-C15 -> -2.1666667 | F15: =IF(E15>0,"Improved",IF(E15<0,"Dropped","Unchanged")) -> Dropped
A16: STU015 | B16: =_xlfn.XLOOKUP(A16,'Cleaned Data'!$A$2:$A$721,'Cleaned Data'!$B$2:$B$721) -> David Oladipo | C16: =AVERAGEIFS('Cleaned Data'!$M$2:$M$721,'Cleaned Data'!$A$2:$A$721,A16,'Cleaned Data'!$E$2:$E$721,"First Term") -> 56 | D16: =AVERAGEIFS('Cleaned Data'!$M$2:$M$721,'Cleaned Data'!$A$2:$A$721,A16,'Cleaned Data'!$E$2:$E$721,"Third Term") -> 61.5 | E16: =D16-C16 -> 5.5 | F16: =IF(E16>0,"Improved",IF(E16<0,"Dropped","Unchanged")) -> Improved | H16: 1. Comfort Okonkwo
A17: STU016 | B17: =_xlfn.XLOOKUP(A17,'Cleaned Data'!$A$2:$A$721,'Cleaned Data'!$B$2:$B$721) -> Tayo Ogundipe | C17: =AVERAGEIFS('Cleaned Data'!$M$2:$M$721,'Cleaned Data'!$A$2:$A$721,A17,'Cleaned Data'!$E$2:$E$721,"First Term") -> 52.333333 | D17: =AVERAGEIFS('Cleaned Data'!$M$2:$M$721,'Cleaned Data'!$A$2:$A$721,A17,'Cleaned Data'!$E$2:$E$721,"Third Term") -> 50.833333 | E17: =D17-C17 -> -1.5 | F17: =IF(E17>0,"Improved",IF(E17<0,"Dropped","Unchanged")) -> Dropped | H17: 2. Daniel Nnadi
A18: STU017 | B18: =_xlfn.XLOOKUP(A18,'Cleaned Data'!$A$2:$A$721,'Cleaned Data'!$B$2:$B$721) -> Ngozi Agu | C18: =AVERAGEIFS('Cleaned Data'!$M$2:$M$721,'Cleaned Data'!$A$2:$A$721,A18,'Cleaned Data'!$E$2:$E$721,"First Term") -> 48.666667 | D18: =AVERAGEIFS('Cleaned Data'!$M$2:$M$721,'Cleaned Data'!$A$2:$A$721,A18,'Cleaned Data'!$E$2:$E$721,"Third Term") -> 46.333333 | E18: =D18-C18 -> -2.3333333 | F18: =IF(E18>0,"Improved",IF(E18<0,"Dropped","Unchanged")) -> Dropped | H18: 3.Ibrahim Nwosu
A19: STU018 | B19: =_xlfn.XLOOKUP(A19,'Cleaned Data'!$A$2:$A$721,'Cleaned Data'!$B$2:$B$721) -> Dayo Williams | C19: =AVERAGEIFS('Cleaned Data'!$M$2:$M$721,'Cleaned Data'!$A$2:$A$721,A19,'Cleaned Data'!$E$2:$E$721,"First Term") -> 47 | D19: =AVERAGEIFS('Cleaned Data'!$M$2:$M$721,'Cleaned Data'!$A$2:$A$721,A19,'Cleaned Data'!$E$2:$E$721,"Third Term") -> 54.333333 | E19: =D19-C19 -> 7.3333333 | F19: =IF(E19>0,"Improved",IF(E19<0,"Dropped","Unchanged")) -> Improved | H19: 4. Nnamdi Ibrahim
A20: STU019 | B20: =_xlfn.XLOOKUP(A20,'Cleaned Data'!$A$2:$A$721,'Cleaned Data'!$B$2:$B$721) -> Grace Olawale | C20: =AVERAGEIFS('Cleaned Data'!$M$2:$M$721,'Cleaned Data'!$A$2:$A$721,A20,'Cleaned Data'!$E$2:$E$721,"First Term") -> 47.333333 | D20: =AVERAGEIFS('Cleaned Data'!$M$2:$M$721,'Cleaned Data'!$A$2:$A$721,A20,'Cleaned Data'!$E$2:$E$721,"Third Term") -> 52.166667 | E20: =D20-C20 -> 4.8333333 | F20: =IF(E20>0,"Improved",IF(E20<0,"Dropped","Unchanged")) -> Improved | H20: 5. Musa Nwankwo
A21: STU020 | B21: =_xlfn.XLOOKUP(A21,'Cleaned Data'!$A$2:$A$721,'Cleaned Data'!$B$2:$B$721) -> Abdullah Akinola | C21: =AVERAGEIFS('Cleaned Data'!$M$2:$M$721,'Cleaned Data'!$A$2:$A$721,A21,'Cleaned Data'!$E$2:$E$721,"First Term") -> 76.5 | D21: =AVERAGEIFS('Cleaned Data'!$M$2:$M$721,'Cleaned Data'!$A$2:$A$721,A21,'Cleaned Data'!$E$2:$E$721,"Third Term") -> 88.833333 | E21: =D21-C21 -> 12.333333 | F21: =IF(E21>0,"Improved",IF(E21<0,"Dropped","Unchanged")) -> Improved
A22: STU021 | B22: =_xlfn.XLOOKUP(A22,'Cleaned Data'!$A$2:$A$721,'Cleaned Data'!$B$2:$B$721) -> John Ajayi | C22: =AVERAGEIFS('Cleaned Data'!$M$2:$M$721,'Cleaned Data'!$A$2:$A$721,A22,'Cleaned Data'!$E$2:$E$721,"First Term") -> 60.333333 | D22: =AVERAGEIFS('Cleaned Data'!$M$2:$M$721,'Cleaned Data'!$A$2:$A$721,A22,'Cleaned Data'!$E$2:$E$721,"Third Term") -> 59.666667 | E22: =D22-C22 -> -0.66666667 | F22: =IF(E22>0,"Improved",IF(E22<0,"Dropped","Unchanged")) -> Dropped
A23: STU022 | B23: =_xlfn.XLOOKUP(A23,'Cleaned Data'!$A$2:$A$721,'Cleaned Data'!$B$2:$B$721) -> Precious Bello | C23: =AVERAGEIFS('Cleaned Data'!$M$2:$M$721,'Cleaned Data'!$A$2:$A$721,A23,'Cleaned Data'!$E$2:$E$721,"First Term") -> 47 | D23: =AVERAGEIFS('Cleaned Data'!$M$2:$M$721,'Cleaned Data'!$A$2:$A$721,A23,'Cleaned Data'!$E$2:$E$721,"Third Term") -> 68.166667 | E23: =D23-C23 -> 21.166667 | F23: =IF(E23>0,"Improved",IF(E23<0,"Dropped","Unchanged")) -> Improved
A24: STU023 | B24: =_xlfn.XLOOKUP(A24,'Cleaned Data'!$A$2:$A$721,'Cleaned Data'!$B$2:$B$721) -> Aminu Kalu | C24: =AVERAGEIFS('Cleaned Data'!$M$2:$M$721,'Cleaned Data'!$A$2:$A$721,A24,'Cleaned Data'!$E$2:$E$721,"First Term") -> 61 | D24: =AVERAGEIFS('Cleaned Data'!$M$2:$M$721,'Cleaned Data'!$A$2:$A$721,A24,'Cleaned Data'!$E$2:$E$721,"Third Term") -> 54.5 | E24: =D24-C24 -> -6.5 | F24: =IF(E24>0,"Improved",IF(E24<0,"Dropped","Unchanged")) -> Dropped
A25: STU024 | B25: =_xlfn.XLOOKUP(A25,'Cleaned Data'!$A$2:$A$721,'Cleaned Data'!$B$2:$B$721) -> Comfort Okonkwo | C25: =AVERAGEIFS('Cleaned Data'!$M$2:$M$721,'Cleaned Data'!$A$2:$A$721,A25,'Cleaned Data'!$E$2:$E$721,"First Term") -> 55 | D25: =AVERAGEIFS('Cleaned Data'!$M$2:$M$721,'Cleaned Data'!$A$2:$A$721,A25,'Cleaned Data'!$E$2:$E$721,"Third Term") -> 84.5 | E25: =D25-C25 -> 29.5 | F25: =IF(E25>0,"Improved",IF(E25<0,"Dropped","Unchanged")) -> Improved | H25: =COUNTIF(F13:F252,"Improved") -> 164 | I25: Improved
A26: STU025 | B26: =_xlfn.XLOOKUP(A26,'Cleaned Data'!$A$2:$A$721,'Cleaned Data'!$B$2:$B$721) -> Adaeze Suleiman | C26: =AVERAGEIFS('Cleaned Data'!$M$2:$M$721,'Cleaned Data'!$A$2:$A$721,A26,'Cleaned Data'!$E$2:$E$721,"First Term") -> 60 | D26: =AVERAGEIFS('Cleaned Data'!$M$2:$M$721,'Cleaned Data'!$A$2:$A$721,A26,'Cleaned Data'!$E$2:$E$721,"Third Term") -> 65.166667 | E26: =D26-C26 -> 5.1666667 | F26: =IF(E26>0,"Improved",IF(E26<0,"Dropped","Unchanged")) -> Improved
A27: STU026 | B27: =_xlfn.XLOOKUP(A27,'Cleaned Data'!$A$2:$A$721,'Cleaned Data'!$B$2:$B$721) -> Grace Akinola | C27: =AVERAGEIFS('Cleaned Data'!$M$2:$M$721,'Cleaned Data'!$A$2:$A$721,A27,'Cleaned Data'!$E$2:$E$721,"First Term") -> 61.166667 | D27: =AVERAGEIFS('Cleaned Data'!$M$2:$M$721,'Cleaned Data'!$A$2:$A$721,A27,'Cleaned Data'!$E$2:$E$721,"Third Term") -> 65.166667 | E27: =D27-C27 -> 4 | F27: =IF(E27>0,"Improved",IF(E27<0,"Dropped","Unchanged")) -> Improved | H27: =COUNTIF(F13:F252,"Dropped") -> 63 | I27: Dropped
A28: STU027 | B28: =_xlfn.XLOOKUP(A28,'Cleaned Data'!$A$2:$A$721,'Cleaned Data'!$B$2:$B$721) -> Patience Umar | C28: =AVERAGEIFS('Cleaned Data'!$M$2:$M$721,'Cleaned Data'!$A$2:$A$721,A28,'Cleaned Data'!$E$2:$E$721,"First Term") -> 45.833333 | D28: =AVERAGEIFS('Cleaned Data'!$M$2:$M$721,'Cleaned Data'!$A$2:$A$721,A28,'Cleaned Data'!$E$2:$E$721,"Third Term") -> 43.166667 | E28: =D28-C28 -> -2.6666667 | F28: =IF(E28>0,"Improved",IF(E28<0,"Dropped","Unchanged")) -> Dropped
A29: STU028 | B29: =_xlfn.XLOOKUP(A29,'Cleaned Data'!$A$2:$A$721,'Cleaned Data'!$B$2:$B$721) -> Chioma Agu | C29: =AVERAGEIFS('Cleaned Data'!$M$2:$M$721,'Cleaned Data'!$A$2:$A$721,A29,'Cleaned Data'!$E$2:$E$721,"First Term") -> 53.666667 | D29: =AVERAGEIFS('Cleaned Data'!$M$2:$M$721,'Cleaned Data'!$A$2:$A$721,A29,'Cleaned Data'!$E$2:$E$721,"Third Term") -> 63.333333 | E29: =D29-C29 -> 9.6666667 | F29: =IF(E29>0,"Improved",IF(E29<0,"Dropped","Unchanged")) -> Improved | H29: =COUNTIF(F13:F252,"Unchanged") -> 2 | I29: Unchanged
A30: STU029 | B30: =_xlfn.XLOOKUP(A30,'Cleaned Data'!$A$2:$A$721,'Cleaned Data'!$B$2:$B$721) -> Ngozi Adewale | C30: =AVERAGEIFS('Cleaned Data'!$M$2:$M$721,'Cleaned Data'!$A$2:$A$721,A30,'Cleaned Data'!$E$2:$E$721,"First Term") -> 67.666667 | D30: =AVERAGEIFS('Cleaned Data'!$M$2:$M$721,'Cleaned Data'!$A$2:$A$721,A30,'Cleaned Data'!$E$2:$E$721,"Third Term") -> 73 | E30: =D30-C30 -> 5.3333333 | F30: =IF(E30>0,"Improved",IF(E30<0,"Dropped","Unchanged")) -> Improved
A31: STU030 | B31: =_xlfn.XLOOKUP(A31,'Cleaned Data'!$A$2:$A$721,'Cleaned Data'!$B$2:$B$721) -> Ebere Ogundipe | C31: =AVERAGEIFS('Cleaned Data'!$M$2:$M$721,'Cleaned Data'!$A$2:$A$721,A31,'Cleaned Data'!$E$2:$E$721,"First Term") -> 58.333333 | D31: =AVERAGEIFS('Cleaned Data'!$M$2:$M$721,'Cleaned Data'!$A$2:$A$721,A31,'Cleaned Data'!$E$2:$E$721,"Third Term") -> 68.333333 | E31: =D31-C31 -> 10 | F31: =IF(E31>0,"Improved",IF(E31<0,"Dropped","Unchanged")) -> Improved
A32: STU031 | B32: =_xlfn.XLOOKUP(A32,'Cleaned Data'!$A$2:$A$721,'Cleaned Data'!$B$2:$B$721) -> Stephen Mohammed | C32: =AVERAGEIFS('Cleaned Data'!$M$2:$M$721,'Cleaned Data'!$A$2:$A$721,A32,'Cleaned Data'!$E$2:$E$721,"First Term") -> 49.333333 | D32: =AVERAGEIFS('Cleaned Data'!$M$2:$M$721,'Cleaned Data'!$A$2:$A$721,A32,'Cleaned Data'!$E$2:$E$721,"Third Term") -> 66.333333 | E32: =D32-C32 -> 17 | F32: =IF(E32>0,"Improved",IF(E32<0,"Dropped","Unchanged")) -> Improved
A33: STU032 | B33: =_xlfn.XLOOKUP(A33,'Cleaned Data'!$A$2:$A$721,'Cleaned Data'!$B$2:$B$721) -> Dare Abubakar | C33: =AVERAGEIFS('Cleaned Data'!$M$2:$M$721,'Cleaned Data'!$A$2:$A$721,A33,'Cleaned Data'!$E$2:$E$721,"First Term") -> 62.833333 | D33: =AVERAGEIFS('Cleaned Data'!$M$2:$M$721,'Cleaned Data'!$A$2:$A$721,A33,'Cleaned Data'!$E$2:$E$721,"Third Term") -> 64.333333 | E33: =D33-C33 -> 1.5 | F33: =IF(E33>0,"Improved",IF(E33<0,"Dropped","Unchanged")) -> Improved
A34: STU033 | B34: =_xlfn.XLOOKUP(A34,'Cleaned Data'!$A$2:$A$721,'Cleaned Data'!$B$2:$B$721) -> Musa Oladipo | C34: =AVERAGEIFS('Cleaned Data'!$M$2:$M$721,'Cleaned Data'!$A$2:$A$721,A34,'Cleaned Data'!$E$2:$E$721,"First Term") -> 66.666667 | D34: =AVERAGEIFS('Cleaned Data'!$M$2:$M$721,'Cleaned Data'!$A$2:$A$721,A34,'Cleaned Data'!$E$2:$E$721,"Third Term") -> 68.666667 | E34: =D34-C34 -> 2 | F34: =IF(E34>0,"Improved",IF(E34<0,"Dropped","Unchanged")) -> Improved
A35: STU034 | B35: =_xlfn.XLOOKUP(A35,'Cleaned Data'!$A$2:$A$721,'Cleaned Data'!$B$2:$B$721) -> Segun Adeyemi | C35: =AVERAGEIFS('Cleaned Data'!$M$2:$M$721,'Cleaned Data'!$A$2:$A$721,A35,'Cleaned Data'!$E$2:$E$721,"First Term") -> 73.666667 | D35: =AVERAGEIFS('Cleaned Data'!$M$2:$M$721,'Cleaned Data'!$A$2:$A$721,A35,'Cleaned Data'!$E$2:$E$721,"Third Term") -> 85.833333 | E35: =D35-C35 -> 12.166667 | F35: =IF(E35>0,"Improved",IF(E35<0,"Dropped","Unchanged")) -> Improved
A36: STU035 | B36: =_xlfn.XLOOKUP(A36,'Cleaned Data'!$A$2:$A$721,'Cleaned Data'!$B$2:$B$721) -> Sani Nwankwo | C36: =AVERAGEIFS('Cleaned Data'!$M$2:$M$721,'Cleaned Data'!$A$2:$A$721,A36,'Cleaned Data'!$E$2:$E$721,"First Term") -> 84.666667 | D36: =AVERAGEIFS('Cleaned Data'!$M$2:$M$721,'Cleaned Data'!$A$2:$A$721,A36,'Cleaned Data'!$E$2:$E$721,"Third Term") -> 76.333333 | E36: =D36-C36 -> -8.3333333 | F36: =IF(E36>0,"Improved",IF(E36<0,"Dropped","Unchanged")) -> Dropped
A37: STU036 | B37: =_xlfn.XLOOKUP(A37,'Cleaned Data'!$A$2:$A$721,'Cleaned Data'!$B$2:$B$721) -> Kemi Danjuma | C37: =AVERAGEIFS('Cleaned Data'!$M$2:$M$721,'Cleaned Data'!$A$2:$A$721,A37,'Cleaned Data'!$E$2:$E$721,"First Term") -> 41.833333 | D37: =AVERAGEIFS('Cleaned Data'!$M$2:$M$721,'Cleaned Data'!$A$2:$A$721,A37,'Cleaned Data'!$E$2:$E$721,"Third Term") -> 38.5 | E37: =D37-C37 -> -3.3333333 | F37: =IF(E37>0,"Improved",IF(E37<0,"Dropped","Unchanged")) -> Dropped
A38: STU037 | B38: =_xlfn.XLOOKUP(A38,'Cleaned Data'!$A$2:$A$721,'Cleaned Data'!$B$2:$B$721) -> Grace Oladipo | C38: =AVERAGEIFS('Cleaned Data'!$M$2:$M$721,'Cleaned Data'!$A$2:$A$721,A38,'Cleaned Data'!$E$2:$E$721,"First Term") -> 60.5 | D38: =AVERAGEIFS('Cleaned Data'!$M$2:$M$721,'Cleaned Data'!$A$2:$A$721,A38,'Cleaned Data'!$E$2:$E$721,"Third Term") -> 68.166667 | E38: =D38-C38 -> 7.6666667 | F38: =IF(E38>0,"Improved",IF(E38<0,"Dropped","Unchanged")) -> Improved
A39: STU038 | B39: =_xlfn.XLOOKUP(A39,'Cleaned Data'!$A$2:$A$721,'Cleaned Data'!$B$2:$B$721) -> Damilola Aliyu | C39: =AVERAGEIFS('Cleaned Data'!$M$2:$M$721,'Cleaned Data'!$A$2:$A$721,A39,'Cleaned Data'!$E$2:$E$721,"First Term") -> 57.833333 | D39: =AVERAGEIFS('Cleaned Data'!$M$2:$M$721,'Cleaned Data'!$A$2:$A$721,A39,'Cleaned Data'!$E$2:$E$721,"Third Term") -> 50.5 | E39: =D39-C39 -> -7.3333333 | F39: =IF(E39>0,"Improved",IF(E39<0,"Dropped","Unchanged")) -> Dropped
A40: STU039 | B40: =_xlfn.XLOOKUP(A40,'Cleaned Data'!$A$2:$A$721,'Cleaned Data'!$B$2:$B$721) -> Babatunde Garba | C40: =AVERAGEIFS('Cleaned Data'!$M$2:$M$721,'Cleaned Data'!$A$2:$A$721,A40,'Cleaned Data'!$E$2:$E$721,"First Term") -> 50.833333 | D40: =AVERAGEIFS('Cleaned Data'!$M$2:$M$721,'Cleaned Data'!$A$2:$A$721,A40,'Cleaned Data'!$E$2:$E$721,"Third Term") -> 58.5 | E40: =D40-C40 -> 7.6666667 | F40: =IF(E40>0,"Improved",IF(E40<0,"Dropped","Unchanged")) -> Improved
...

Sheet Risk
A1: STUDENT ID | B1: STUDENT NAME | C1: THIRD TERM AVERAGE
A2: STU002 | B2: Damilola Danjuma | C2: 49
A3: STU017 | B3: Ngozi Agu | C3: 46.333333
A4: STU027 | B4: Patience Umar | C4: 43.166667
A5: STU036 | B5: Kemi Danjuma | C5: 38.5
A6: STU053 | B6: Garba Adebayo | C6: 49.166667
A7: STU056 | B7: Esther Nnadi | C7: 48
A8: STU063 | B8: Oluwaseun Balogun | C8: 45
A9: STU076 | B9: Bello Eze | C9: 45.833333
A10: STU081 | B10: Folake Aliyu | C10: 48.666667
A11: STU103 | B11: Ngozi Olawale | C11: 33.833333
A12: STU104 | B12: Funmilayo Uzor | C12: 34.166667
A13: STU106 | B13: Mercy Ibrahim | C13: 49
... A33: STU239 | B33: Victoria Nnadi | C33: 28

Sheet Summary
